<sdf version='1.7'>
  <model name='ur'>
    <joint name='base_joint' type='fixed'>
      <pose relative_to='__model__'>0 0 0 0 -0 0</pose>
      <parent>world</parent>
      <child>base_link</child>
    </joint>
    <link name='base_link'>
      <pose relative_to='base_joint'>0 0 0 0 -0 0</pose>
      <inertial>
        <pose>0 0 0 0 -0 0</pose>
        <mass>4</mass>
        <inertia>
          <ixx>0.00610633</ixx>
          <ixy>0</ixy>
          <ixz>0</ixz>
          <iyy>0.00610633</iyy>
          <iyz>0</iyz>
          <izz>0.01125</izz>
        </inertia>
      </inertial>
      <collision name='base_link_inertia_collision'>
        <pose>0 0 0 0 0 -0</pose>
        <geometry>
          <mesh>
            <scale>1 1 1</scale>
            <uri>/home/dcbothra2204/arm_manip/install/ur_description/share/ur_description/meshes/ur10e/collision/base.stl</uri>
          </mesh>
        </geometry>
      </collision>
      <visual name='base_link_inertia_visual'>
        <pose>0 0 0 0 0 -0</pose>
        <geometry>
          <mesh>
            <scale>1 1 1</scale>
            <uri>/home/dcbothra2204/arm_manip/install/ur_description/share/ur_description/meshes/ur10e/visual/base.dae</uri>
          </mesh>
        </geometry>
      </visual>
    </link>
    <joint name='shoulder_pan_joint' type='revolute'>
      <pose relative_to='base_link'>0 0 0.1807 0 -0 3.14159</pose>
      <parent>base_link</parent>
      <child>shoulder_link</child>
      <axis>
        <xyz>0 0 1</xyz>
        <limit>
          <lower>-6.28319</lower>
          <upper>6.28319</upper>
          <effort>330</effort>
          <velocity>2.0944</velocity>
        </limit>
        <dynamics>
          <damping>0</damping>
          <friction>0</friction>
          <spring_reference>0</spring_reference>
          <spring_stiffness>0</spring_stiffness>
        </dynamics>
      </axis>
    </joint>
    <link name='shoulder_link'>
      <pose relative_to='shoulder_pan_joint'>0 0 0 0 -0 0</pose>
      <inertial>
        <pose>0.021 -0.027 0 1.5708 -0 0</pose>
        <mass>7.369</mass>
        <inertia>
          <ixx>0.03408</ixx>
          <ixy>2e-05</ixy>
          <ixz>-0.00425</ixz>
          <iyy>0.03529</iyy>
          <iyz>8e-05</iyz>
          <izz>0.02156</izz>
        </inertia>
      </inertial>
      <collision name='shoulder_link_collision'>
        <pose>0 0 0 0 -0 3.14159</pose>
        <geometry>
          <mesh>
            <scale>1 1 1</scale>
            <uri>/home/dcbothra2204/arm_manip/install/ur_description/share/ur_description/meshes/ur10e/collision/shoulder.stl</uri>
          </mesh>
        </geometry>
      </collision>
      <visual name='shoulder_link_visual'>
        <pose>0 0 0 0 -0 3.14159</pose>
        <geometry>
          <mesh>
            <scale>1 1 1</scale>
            <uri>/home/dcbothra2204/arm_manip/install/ur_description/share/ur_description/meshes/ur10e/visual/shoulder.dae</uri>
          </mesh>
        </geometry>
      </visual>
    </link>
    <joint name='shoulder_lift_joint' type='revolute'>
      <pose relative_to='shoulder_link'>0 0 0 1.5708 -0 0</pose>
      <parent>shoulder_link</parent>
      <child>upper_arm_link</child>
      <axis>
        <xyz>0 0 1</xyz>
        <limit>
          <lower>-6.28319</lower>
          <upper>6.28319</upper>
          <effort>330</effort>
          <velocity>2.0944</velocity>
        </limit>
        <dynamics>
          <damping>0</damping>
          <friction>0</friction>
          <spring_reference>0</spring_reference>
          <spring_stiffness>0</spring_stiffness>
        </dynamics>
      </axis>
    </joint>
    <link name='upper_arm_link'>
      <pose relative_to='shoulder_lift_joint'>0 0 0 0 -0 0</pose>
      <inertial>
        <pose>-0.2327 0 0.158 0 -0 0</pose>
        <mass>13.051</mass>
        <inertia>
          <ixx>0.02814</ixx>
          <ixy>5e-05</ixy>
          <ixz>-0.01561</ixz>
          <iyy>0.77068</iyy>
          <iyz>2e-05</iyz>
          <izz>0.76943</izz>
        </inertia>
      </inertial>
      <collision name='upper_arm_link_collision'>
        <pose>0 0 0.1762 1.5708 0 -1.5708</pose>
        <geometry>
          <mesh>
            <scale>1 1 1</scale>
            <uri>/home/dcbothra2204/arm_manip/install/ur_description/share/ur_description/meshes/ur10e/collision/upperarm.stl</uri>
          </mesh>
        </geometry>
      </collision>
      <visual name='upper_arm_link_visual'>
        <pose>0 0 0.1762 1.5708 0 -1.5708</pose>
        <geometry>
          <mesh>
            <scale>1 1 1</scale>
            <uri>/home/dcbothra2204/arm_manip/install/ur_description/share/ur_description/meshes/ur10e/visual/upperarm.dae</uri>
          </mesh>
        </geometry>
      </visual>
    </link>
    <joint name='elbow_joint' type='revolute'>
      <pose relative_to='upper_arm_link'>-0.6127 0 0 0 -0 0</pose>
      <parent>upper_arm_link</parent>
      <child>forearm_link</child>
      <axis>
        <xyz>0 0 1</xyz>
        <limit>
          <lower>-3.14159</lower>
          <upper>3.14159</upper>
          <effort>150</effort>
          <velocity>3.14159</velocity>
        </limit>
        <dynamics>
          <damping>0</damping>
          <friction>0</friction>
          <spring_reference>0</spring_reference>
          <spring_stiffness>0</spring_stiffness>
        </dynamics>
      </axis>
    </joint>
    <link name='forearm_link'>
      <pose relative_to='elbow_joint'>0 0 0 0 -0 0</pose>
      <inertial>
        <pose>-0.33155 0 0.068 0 -0 0</pose>
        <mass>3.989</mass>
        <inertia>
          <ixx>0.01014</ixx>
          <ixy>8e-05</ixy>
          <ixz>0.00916</ixz>
          <iyy>0.30928</iyy>
          <iyz>0</iyz>
          <izz>0.30646</izz>
        </inertia>
      </inertial>
      <collision name='forearm_link_collision'>
        <pose>0 0 0.0393 1.5708 0 -1.5708</pose>
        <geometry>
          <mesh>
            <scale>1 1 1</scale>
            <uri>/home/dcbothra2204/arm_manip/install/ur_description/share/ur_description/meshes/ur10e/collision/forearm.stl</uri>
          </mesh>
        </geometry>
      </collision>
      <visual name='forearm_link_visual'>
        <pose>0 0 0.0393 1.5708 0 -1.5708</pose>
        <geometry>
          <mesh>
            <scale>1 1 1</scale>
            <uri>/home/dcbothra2204/arm_manip/install/ur_description/share/ur_description/meshes/ur10e/visual/forearm.dae</uri>
          </mesh>
        </geometry>
      </visual>
    </link>
    <joint name='wrist_1_joint' type='revolute'>
      <pose relative_to='forearm_link'>-0.57155 0 0.17415 0 -0 0</pose>
      <parent>forearm_link</parent>
      <child>wrist_1_link</child>
      <axis>
        <xyz>0 0 1</xyz>
        <limit>
          <lower>-6.28319</lower>
          <upper>6.28319</upper>
          <effort>54</effort>
          <velocity>3.14159</velocity>
        </limit>
        <dynamics>
          <damping>0</damping>
          <friction>0</friction>
          <spring_reference>0</spring_reference>
          <spring_stiffness>0</spring_stiffness>
        </dynamics>
      </axis>
    </joint>
    <link name='wrist_1_link'>
      <pose relative_to='wrist_1_joint'>0 0 0 0 -0 0</pose>
      <inertial>
        <pose>0 -0.018 0.007 1.5708 -0 0</pose>
        <mass>2.1</mass>
        <inertia>
          <ixx>0.00296</ixx>
          <ixy>-1e-05</ixy>
          <ixz>0</ixz>
          <iyy>0.00222</iyy>
          <iyz>-0.00024</iyz>
          <izz>0.00258</izz>
        </inertia>
      </inertial>
      <collision name='wrist_1_link_collision'>
        <pose>0 0 -0.135 1.5708 -0 0</pose>
        <geometry>
          <mesh>
            <scale>1 1 1</scale>
            <uri>/home/dcbothra2204/arm_manip/install/ur_description/share/ur_description/meshes/ur10e/collision/wrist1.stl</uri>
          </mesh>
        </geometry>
      </collision>
      <visual name='wrist_1_link_visual'>
        <pose>0 0 -0.135 1.5708 -0 0</pose>
        <geometry>
          <mesh>
            <scale>1 1 1</scale>
            <uri>/home/dcbothra2204/arm_manip/install/ur_description/share/ur_description/meshes/ur10e/visual/wrist1.dae</uri>
          </mesh>
        </geometry>
      </visual>
    </link>
    <joint name='wrist_2_joint' type='revolute'>
      <pose relative_to='wrist_1_link'>0 -0.11985 -0 1.5708 -0 0</pose>
      <parent>wrist_1_link</parent>
      <child>wrist_2_link</child>
      <axis>
        <xyz>0 0 1</xyz>
        <limit>
          <lower>-6.28319</lower>
          <upper>6.28319</upper>
          <effort>54</effort>
          <velocity>3.14159</velocity>
        </limit>
        <dynamics>
          <damping>0</damping>
          <friction>0</friction>
          <spring_reference>0</spring_reference>
          <spring_stiffness>0</spring_stiffness>
        </dynamics>
      </axis>
    </joint>
    <link name='wrist_2_link'>
      <pose relative_to='wrist_2_joint'>0 0 0 0 -0 0</pose>
      <inertial>
        <pose>0 0.018 -0.007 -1.5708 0 0</pose>
        <mass>1.98</mass>
        <inertia>
          <ixx>0.00296</ixx>
          <ixy>-1e-05</ixy>
          <ixz>0</ixz>
          <iyy>0.00222</iyy>
          <iyz>-0.00024</iyz>
          <izz>0.00258</izz>
        </inertia>
      </inertial>
      <collision name='wrist_2_link_collision'>
        <pose>0 0 -0.12 0 -0 0</pose>
        <geometry>
          <mesh>
            <scale>1 1 1</scale>
            <uri>/home/dcbothra2204/arm_manip/install/ur_description/share/ur_description/meshes/ur10e/collision/wrist2.stl</uri>
          </mesh>
        </geometry>
      </collision>
      <visual name='wrist_2_link_visual'>
        <pose>0 0 -0.12 0 -0 0</pose>
        <geometry>
          <mesh>
            <scale>1 1 1</scale>
            <uri>/home/dcbothra2204/arm_manip/install/ur_description/share/ur_description/meshes/ur10e/visual/wrist2.dae</uri>
          </mesh>
        </geometry>
      </visual>
    </link>
    <joint name='wrist_3_joint' type='revolute'>
      <pose relative_to='wrist_2_link'>0 0.11655 -0 -1.5708 0 -0</pose>
      <parent>wrist_2_link</parent>
      <child>wrist_3_link</child>
      <axis>
        <xyz>0 0 1</xyz>
        <limit>
          <lower>-6.28319</lower>
          <upper>6.28319</upper>
          <effort>54</effort>
          <velocity>3.14159</velocity>
        </limit>
        <dynamics>
          <damping>0</damping>
          <friction>0</friction>
          <spring_reference>0</spring_reference>
          <spring_stiffness>0</spring_stiffness>
        </dynamics>
      </axis>
    </joint>
    <link name='wrist_3_link'>
      <pose relative_to='wrist_3_joint'>0 0 0 0 -0 0</pose>
      <inertial>
        <pose>0 0 -0.026 0 -0 0</pose>
        <mass>0.615</mass>
        <inertia>
          <ixx>0.0004</ixx>
          <ixy>0</ixy>
          <ixz>0</ixz>
          <iyy>0.00041</iyy>
          <iyz>0</iyz>
          <izz>0.00034</izz>
        </inertia>
      </inertial>
      <collision name='wrist_3_link_collision'>
        <pose>0 0 -0.1168 1.5708 -0 0</pose>
        <geometry>
          <mesh>
            <scale>1 1 1</scale>
            <uri>/home/dcbothra2204/arm_manip/install/ur_description/share/ur_description/meshes/ur10e/collision/wrist3.stl</uri>
          </mesh>
        </geometry>
      </collision>
      <visual name='wrist_3_link_visual'>
        <pose>0 0 -0.1168 1.5708 -0 0</pose>
        <geometry>
          <mesh>
            <scale>1 1 1</scale>
            <uri>/home/dcbothra2204/arm_manip/install/ur_description/share/ur_description/meshes/ur10e/visual/wrist3.dae</uri>
          </mesh>
        </geometry>
      </visual>
    </link>
    <static>0</static>
    <plugin name='gazebo_ros2_control' filename='libgazebo_ros2_control.so'/>
  </model>
</sdf>
